[2024-08-22 06:20:06 +0000] [9906] [INFO] Starting gunicorn 23.0.0
[2024-08-22 06:20:06 +0000] [9906] [INFO] Listening at: http://0.0.0.0:8000 (9906)
[2024-08-22 06:20:06 +0000] [9906] [INFO] Using worker: uvicorn.workers.UvicornWorker
[2024-08-22 06:20:06 +0000] [9907] [INFO] Booting worker with pid: 9907
[2024-08-22 06:20:06 +0000] [9908] [INFO] Booting worker with pid: 9908
[2024-08-22 06:20:06 +0000] [9909] [INFO] Booting worker with pid: 9909
[2024-08-22 06:20:06 +0000] [9910] [INFO] Booting worker with pid: 9910
[2024-08-22 06:20:07 +0000] [9907] [INFO] Started server process [9907]
[2024-08-22 06:20:07 +0000] [9907] [INFO] Waiting for application startup.
[2024-08-22 06:20:07 +0000] [9907] [INFO] Application startup complete.
[2024-08-22 06:20:07 +0000] [9908] [INFO] Started server process [9908]
[2024-08-22 06:20:07 +0000] [9908] [INFO] Waiting for application startup.
[2024-08-22 06:20:07 +0000] [9908] [INFO] Application startup complete.
[2024-08-22 06:20:07 +0000] [9909] [INFO] Started server process [9909]
[2024-08-22 06:20:07 +0000] [9909] [INFO] Waiting for application startup.
[2024-08-22 06:20:07 +0000] [9909] [INFO] Application startup complete.
[2024-08-22 06:20:07 +0000] [9910] [INFO] Started server process [9910]
[2024-08-22 06:20:07 +0000] [9910] [INFO] Waiting for application startup.
[2024-08-22 06:20:07 +0000] [9910] [INFO] Application startup complete.
[2024-08-22 06:20:51 +0000] [9910] [ERROR] Exception in ASGI application
Traceback (most recent call last):
  File "/home/ubuntu/Document-backend/venv/lib/python3.12/site-packages/sqlalchemy/engine/base.py", line 1967, in _exec_single_context
    self.dialect.do_execute(
  File "/home/ubuntu/Document-backend/venv/lib/python3.12/site-packages/sqlalchemy/engine/default.py", line 941, in do_execute
    cursor.execute(statement, parameters)
  File "/home/ubuntu/Document-backend/venv/lib/python3.12/site-packages/pymysql/cursors.py", line 153, in execute
    result = self._query(query)
             ^^^^^^^^^^^^^^^^^^
  File "/home/ubuntu/Document-backend/venv/lib/python3.12/site-packages/pymysql/cursors.py", line 322, in _query
    conn.query(q)
  File "/home/ubuntu/Document-backend/venv/lib/python3.12/site-packages/pymysql/connections.py", line 563, in query
    self._affected_rows = self._read_query_result(unbuffered=unbuffered)
                          ^^^^^^^^^^^^^^^^^^^^^^^^^^^^^^^^^^^^^^^^^^^^^^
  File "/home/ubuntu/Document-backend/venv/lib/python3.12/site-packages/pymysql/connections.py", line 825, in _read_query_result
    result.read()
  File "/home/ubuntu/Document-backend/venv/lib/python3.12/site-packages/pymysql/connections.py", line 1199, in read
    first_packet = self.connection._read_packet()
                   ^^^^^^^^^^^^^^^^^^^^^^^^^^^^^^
  File "/home/ubuntu/Document-backend/venv/lib/python3.12/site-packages/pymysql/connections.py", line 775, in _read_packet
    packet.raise_for_error()
  File "/home/ubuntu/Document-backend/venv/lib/python3.12/site-packages/pymysql/protocol.py", line 219, in raise_for_error
    err.raise_mysql_exception(self._data)
  File "/home/ubuntu/Document-backend/venv/lib/python3.12/site-packages/pymysql/err.py", line 150, in raise_mysql_exception
    raise errorclass(errno, errval)
pymysql.err.ProgrammingError: (1146, "Table 'doculens_db.admin_users' doesn't exist")

The above exception was the direct cause of the following exception:

Traceback (most recent call last):
  File "/home/ubuntu/Document-backend/venv/lib/python3.12/site-packages/uvicorn/protocols/http/httptools_impl.py", line 401, in run_asgi
    result = await app(  # type: ignore[func-returns-value]
             ^^^^^^^^^^^^^^^^^^^^^^^^^^^^^^^^^^^^^^^^^^^^^^
  File "/home/ubuntu/Document-backend/venv/lib/python3.12/site-packages/uvicorn/middleware/proxy_headers.py", line 70, in __call__
    return await self.app(scope, receive, send)
           ^^^^^^^^^^^^^^^^^^^^^^^^^^^^^^^^^^^^
  File "/home/ubuntu/Document-backend/venv/lib/python3.12/site-packages/fastapi/applications.py", line 1054, in __call__
    await super().__call__(scope, receive, send)
  File "/home/ubuntu/Document-backend/venv/lib/python3.12/site-packages/starlette/applications.py", line 123, in __call__
    await self.middleware_stack(scope, receive, send)
  File "/home/ubuntu/Document-backend/venv/lib/python3.12/site-packages/starlette/middleware/errors.py", line 186, in __call__
    raise exc
  File "/home/ubuntu/Document-backend/venv/lib/python3.12/site-packages/starlette/middleware/errors.py", line 164, in __call__
    await self.app(scope, receive, _send)
  File "/home/ubuntu/Document-backend/venv/lib/python3.12/site-packages/starlette/middleware/cors.py", line 93, in __call__
    await self.simple_response(scope, receive, send, request_headers=headers)
  File "/home/ubuntu/Document-backend/venv/lib/python3.12/site-packages/starlette/middleware/cors.py", line 148, in simple_response
    await self.app(scope, receive, send)
  File "/home/ubuntu/Document-backend/venv/lib/python3.12/site-packages/starlette/middleware/exceptions.py", line 65, in __call__
    await wrap_app_handling_exceptions(self.app, conn)(scope, receive, send)
  File "/home/ubuntu/Document-backend/venv/lib/python3.12/site-packages/starlette/_exception_handler.py", line 64, in wrapped_app
    raise exc
  File "/home/ubuntu/Document-backend/venv/lib/python3.12/site-packages/starlette/_exception_handler.py", line 53, in wrapped_app
    await app(scope, receive, sender)
  File "/home/ubuntu/Document-backend/venv/lib/python3.12/site-packages/starlette/routing.py", line 756, in __call__
    await self.middleware_stack(scope, receive, send)
  File "/home/ubuntu/Document-backend/venv/lib/python3.12/site-packages/starlette/routing.py", line 776, in app
    await route.handle(scope, receive, send)
  File "/home/ubuntu/Document-backend/venv/lib/python3.12/site-packages/starlette/routing.py", line 297, in handle
    await self.app(scope, receive, send)
  File "/home/ubuntu/Document-backend/venv/lib/python3.12/site-packages/starlette/routing.py", line 77, in app
    await wrap_app_handling_exceptions(app, request)(scope, receive, send)
  File "/home/ubuntu/Document-backend/venv/lib/python3.12/site-packages/starlette/_exception_handler.py", line 64, in wrapped_app
    raise exc
  File "/home/ubuntu/Document-backend/venv/lib/python3.12/site-packages/starlette/_exception_handler.py", line 53, in wrapped_app
    await app(scope, receive, sender)
  File "/home/ubuntu/Document-backend/venv/lib/python3.12/site-packages/starlette/routing.py", line 72, in app
    response = await func(request)
               ^^^^^^^^^^^^^^^^^^^
  File "/home/ubuntu/Document-backend/venv/lib/python3.12/site-packages/fastapi/routing.py", line 278, in app
    raw_response = await run_endpoint_function(
                   ^^^^^^^^^^^^^^^^^^^^^^^^^^^^
  File "/home/ubuntu/Document-backend/venv/lib/python3.12/site-packages/fastapi/routing.py", line 193, in run_endpoint_function
    return await run_in_threadpool(dependant.call, **values)
           ^^^^^^^^^^^^^^^^^^^^^^^^^^^^^^^^^^^^^^^^^^^^^^^^^
  File "/home/ubuntu/Document-backend/venv/lib/python3.12/site-packages/starlette/concurrency.py", line 42, in run_in_threadpool
    return await anyio.to_thread.run_sync(func, *args)
           ^^^^^^^^^^^^^^^^^^^^^^^^^^^^^^^^^^^^^^^^^^^
  File "/home/ubuntu/Document-backend/venv/lib/python3.12/site-packages/anyio/to_thread.py", line 56, in run_sync
    return await get_async_backend().run_sync_in_worker_thread(
           ^^^^^^^^^^^^^^^^^^^^^^^^^^^^^^^^^^^^^^^^^^^^^^^^^^^^
  File "/home/ubuntu/Document-backend/venv/lib/python3.12/site-packages/anyio/_backends/_asyncio.py", line 2177, in run_sync_in_worker_thread
    return await future
           ^^^^^^^^^^^^
  File "/home/ubuntu/Document-backend/venv/lib/python3.12/site-packages/anyio/_backends/_asyncio.py", line 859, in run
    result = context.run(func, *args)
             ^^^^^^^^^^^^^^^^^^^^^^^^
  File "/home/ubuntu/Document-backend/app/routers/admin/api.py", line 42, in register
    data = admin_users.register(db, request)
           ^^^^^^^^^^^^^^^^^^^^^^^^^^^^^^^^^
  File "/home/ubuntu/Document-backend/app/routers/admin/crud/admin_users.py", line 100, in register
    db_admin_user = get_admin_user_by_email(db, email=request.email)
                    ^^^^^^^^^^^^^^^^^^^^^^^^^^^^^^^^^^^^^^^^^^^^^^^^
  File "/home/ubuntu/Document-backend/app/routers/admin/crud/admin_users.py", line 96, in get_admin_user_by_email
    .first()
     ^^^^^^^
  File "/home/ubuntu/Document-backend/venv/lib/python3.12/site-packages/sqlalchemy/orm/query.py", line 2728, in first
    return self.limit(1)._iter().first()  # type: ignore
           ^^^^^^^^^^^^^^^^^^^^^
  File "/home/ubuntu/Document-backend/venv/lib/python3.12/site-packages/sqlalchemy/orm/query.py", line 2827, in _iter
    result: Union[ScalarResult[_T], Result[_T]] = self.session.execute(
                                                  ^^^^^^^^^^^^^^^^^^^^^
  File "/home/ubuntu/Document-backend/venv/lib/python3.12/site-packages/sqlalchemy/orm/session.py", line 2362, in execute
    return self._execute_internal(
           ^^^^^^^^^^^^^^^^^^^^^^^
  File "/home/ubuntu/Document-backend/venv/lib/python3.12/site-packages/sqlalchemy/orm/session.py", line 2247, in _execute_internal
    result: Result[Any] = compile_state_cls.orm_execute_statement(
                          ^^^^^^^^^^^^^^^^^^^^^^^^^^^^^^^^^^^^^^^^
  File "/home/ubuntu/Document-backend/venv/lib/python3.12/site-packages/sqlalchemy/orm/context.py", line 293, in orm_execute_statement
    result = conn.execute(
             ^^^^^^^^^^^^^
  File "/home/ubuntu/Document-backend/venv/lib/python3.12/site-packages/sqlalchemy/engine/base.py", line 1418, in execute
    return meth(
           ^^^^^
  File "/home/ubuntu/Document-backend/venv/lib/python3.12/site-packages/sqlalchemy/sql/elements.py", line 515, in _execute_on_connection
    return connection._execute_clauseelement(
           ^^^^^^^^^^^^^^^^^^^^^^^^^^^^^^^^^^
  File "/home/ubuntu/Document-backend/venv/lib/python3.12/site-packages/sqlalchemy/engine/base.py", line 1640, in _execute_clauseelement
    ret = self._execute_context(
          ^^^^^^^^^^^^^^^^^^^^^^
  File "/home/ubuntu/Document-backend/venv/lib/python3.12/site-packages/sqlalchemy/engine/base.py", line 1846, in _execute_context
    return self._exec_single_context(
           ^^^^^^^^^^^^^^^^^^^^^^^^^^
  File "/home/ubuntu/Document-backend/venv/lib/python3.12/site-packages/sqlalchemy/engine/base.py", line 1986, in _exec_single_context
    self._handle_dbapi_exception(
  File "/home/ubuntu/Document-backend/venv/lib/python3.12/site-packages/sqlalchemy/engine/base.py", line 2355, in _handle_dbapi_exception
    raise sqlalchemy_exception.with_traceback(exc_info[2]) from e
  File "/home/ubuntu/Document-backend/venv/lib/python3.12/site-packages/sqlalchemy/engine/base.py", line 1967, in _exec_single_context
    self.dialect.do_execute(
  File "/home/ubuntu/Document-backend/venv/lib/python3.12/site-packages/sqlalchemy/engine/default.py", line 941, in do_execute
    cursor.execute(statement, parameters)
  File "/home/ubuntu/Document-backend/venv/lib/python3.12/site-packages/pymysql/cursors.py", line 153, in execute
    result = self._query(query)
             ^^^^^^^^^^^^^^^^^^
  File "/home/ubuntu/Document-backend/venv/lib/python3.12/site-packages/pymysql/cursors.py", line 322, in _query
    conn.query(q)
  File "/home/ubuntu/Document-backend/venv/lib/python3.12/site-packages/pymysql/connections.py", line 563, in query
    self._affected_rows = self._read_query_result(unbuffered=unbuffered)
                          ^^^^^^^^^^^^^^^^^^^^^^^^^^^^^^^^^^^^^^^^^^^^^^
  File "/home/ubuntu/Document-backend/venv/lib/python3.12/site-packages/pymysql/connections.py", line 825, in _read_query_result
    result.read()
  File "/home/ubuntu/Document-backend/venv/lib/python3.12/site-packages/pymysql/connections.py", line 1199, in read
    first_packet = self.connection._read_packet()
                   ^^^^^^^^^^^^^^^^^^^^^^^^^^^^^^
  File "/home/ubuntu/Document-backend/venv/lib/python3.12/site-packages/pymysql/connections.py", line 775, in _read_packet
    packet.raise_for_error()
  File "/home/ubuntu/Document-backend/venv/lib/python3.12/site-packages/pymysql/protocol.py", line 219, in raise_for_error
    err.raise_mysql_exception(self._data)
  File "/home/ubuntu/Document-backend/venv/lib/python3.12/site-packages/pymysql/err.py", line 150, in raise_mysql_exception
    raise errorclass(errno, errval)
sqlalchemy.exc.ProgrammingError: (pymysql.err.ProgrammingError) (1146, "Table 'doculens_db.admin_users' doesn't exist")
[SQL: SELECT admin_users.id AS admin_users_id, admin_users.name AS admin_users_name, admin_users.email AS admin_users_email, admin_users.phone AS admin_users_phone, admin_users.password AS admin_users_password, admin_users.is_registered AS admin_users_is_registered, admin_users.verification_token AS admin_users_verification_token, admin_users.is_deleted AS admin_users_is_deleted, admin_users.created_at AS admin_users_created_at, admin_users.updated_at AS admin_users_updated_at 
FROM admin_users 
WHERE admin_users.email = %(email_1)s AND admin_users.is_deleted = false 
 LIMIT %(param_1)s]
[parameters: {'email_1': 'mantra.gor@aeonx.digital', 'param_1': 1}]
(Background on this error at: https://sqlalche.me/e/20/f405)
[2024-08-22 06:34:43 +0000] [9906] [INFO] Handling signal: term
[2024-08-22 06:34:43 +0000] [9909] [INFO] Shutting down
[2024-08-22 06:34:43 +0000] [9909] [INFO] Error while closing socket [Errno 9] Bad file descriptor
[2024-08-22 06:34:43 +0000] [9908] [INFO] Shutting down
[2024-08-22 06:34:43 +0000] [9908] [INFO] Error while closing socket [Errno 9] Bad file descriptor
[2024-08-22 06:34:43 +0000] [9910] [INFO] Shutting down
[2024-08-22 06:34:43 +0000] [9910] [INFO] Error while closing socket [Errno 9] Bad file descriptor
[2024-08-22 06:34:43 +0000] [9907] [INFO] Shutting down
[2024-08-22 06:34:43 +0000] [9907] [INFO] Error while closing socket [Errno 9] Bad file descriptor
[2024-08-22 06:34:43 +0000] [9909] [INFO] Waiting for application shutdown.
[2024-08-22 06:34:43 +0000] [9909] [INFO] Application shutdown complete.
[2024-08-22 06:34:43 +0000] [9909] [INFO] Finished server process [9909]
[2024-08-22 06:34:43 +0000] [9906] [ERROR] Worker (pid:9909) was sent SIGTERM!
[2024-08-22 06:34:43 +0000] [9908] [INFO] Waiting for application shutdown.
[2024-08-22 06:34:43 +0000] [9908] [INFO] Application shutdown complete.
[2024-08-22 06:34:43 +0000] [9908] [INFO] Finished server process [9908]
[2024-08-22 06:34:43 +0000] [9906] [ERROR] Worker (pid:9908) was sent SIGTERM!
[2024-08-22 06:34:43 +0000] [9910] [INFO] Waiting for application shutdown.
[2024-08-22 06:34:43 +0000] [9910] [INFO] Application shutdown complete.
[2024-08-22 06:34:43 +0000] [9910] [INFO] Finished server process [9910]
[2024-08-22 06:34:43 +0000] [9906] [ERROR] Worker (pid:9910) was sent SIGTERM!
[2024-08-22 06:34:43 +0000] [9907] [INFO] Waiting for application shutdown.
[2024-08-22 06:34:43 +0000] [9907] [INFO] Application shutdown complete.
[2024-08-22 06:34:43 +0000] [9907] [INFO] Finished server process [9907]
[2024-08-22 06:34:43 +0000] [9906] [ERROR] Worker (pid:9907) was sent SIGTERM!
[2024-08-22 06:34:43 +0000] [9906] [INFO] Shutting down: Master
[2024-08-22 06:34:43 +0000] [15023] [INFO] Starting gunicorn 23.0.0
[2024-08-22 06:34:43 +0000] [15023] [INFO] Listening at: http://0.0.0.0:8000 (15023)
[2024-08-22 06:34:43 +0000] [15023] [INFO] Using worker: uvicorn.workers.UvicornWorker
[2024-08-22 06:34:43 +0000] [15032] [INFO] Booting worker with pid: 15032
[2024-08-22 06:34:44 +0000] [15037] [INFO] Booting worker with pid: 15037
[2024-08-22 06:34:44 +0000] [15039] [INFO] Booting worker with pid: 15039
[2024-08-22 06:34:44 +0000] [15041] [INFO] Booting worker with pid: 15041
[2024-08-22 06:34:44 +0000] [15032] [INFO] Started server process [15032]
[2024-08-22 06:34:44 +0000] [15032] [INFO] Waiting for application startup.
[2024-08-22 06:34:44 +0000] [15032] [INFO] Application startup complete.
[2024-08-22 06:34:44 +0000] [15037] [INFO] Started server process [15037]
[2024-08-22 06:34:44 +0000] [15037] [INFO] Waiting for application startup.
[2024-08-22 06:34:44 +0000] [15037] [INFO] Application startup complete.
[2024-08-22 06:34:44 +0000] [15039] [INFO] Started server process [15039]
[2024-08-22 06:34:44 +0000] [15039] [INFO] Waiting for application startup.
[2024-08-22 06:34:44 +0000] [15039] [INFO] Application startup complete.
[2024-08-22 06:34:45 +0000] [15041] [INFO] Started server process [15041]
[2024-08-22 06:34:45 +0000] [15041] [INFO] Waiting for application startup.
[2024-08-22 06:34:45 +0000] [15041] [INFO] Application startup complete.
